Workbook

Sheet Cover Notes
A1: Wipro Enterprises (P) Limited - Standalone Financial Statements
A2: FY 2020-21, FY 2021-22, FY 2022-23, FY 2023-24 and FY 2024-25
A4: This workbook compiles the Standalone financial statements as reported in the audited Annual Reports of
A5: Wipro Enterprises (P) Limited for FY2020-21, FY2021-22, FY2022-23, FY2023-24 and FY2024-25.
A7: Scope and basis of preparation:
A8: - All figures are STANDALONE (not consolidated), as reported in each year's Annual Report, in Rs. millions.
A9: - Figures are transcribed exactly as printed in the source PDFs - no figures have been altered, recalculated, or restated by
A10: this workbook. Where a later annual report restated a prior year (e.g. FY2021 figures restated for a merger in the
A11: FY2021-22 report, marked with *), both the original and the restated figures are preserved in their respective year's sheet.
A12: - "*" symbols used in source reports to denote amounts below Rs. 0.5 million (rounding) have been entered as 0.
A13: - Each statement/notes sheet cites its exact source document and page number.
A15: Sheets included per year: Balance Sheet, Statement of Profit and Loss, Statement of Cash Flows, and a Notes to Accounts
... A36: instruction not to change any figures.

Sheet PL 2020-21
A1: Wipro Enterprises (P) Limited (Standalone)
A2: Statement of Profit and Loss
A3: Statement of Profit and Loss for the year ended March 31, 2021 (Source: Annual Report 2020-21, p.59)
A4: (Amount Rs. in millions, unless otherwise stated)
A6: Particulars | B6: 2021 | C6: 2020
A7: REVENUE
A8: Revenue from operations | B8: 51658 | C8: 47775
A9: Other income | B9: 6905 | C9: 4900
A10: Total income | B10: 58563 | C10: 52675
A11: EXPENSES
A12: Cost of materials consumed | B12: 21255 | C12: 16125
A13: Purchases of stock-in-trade | B13: 8407 | C13: 9470
A14: Changes in inventories of finished products, WIP and stock-in-trade | B14: 341 | C14: -288
A15: Employee benefits expense | B15: 4518 | C15: 4077
A16: Finance costs | B16: 762 | C16: 113
A17: Depreciation and amortisation expense | B17: 914 | C17: 956
A18: Other expenses | B18: 11101 | C18: 11893
A19: Total expenses | B19: 47298 | C19: 42347
A20: Profit before tax | B20: 11265 | C20: 10328
A21: Tax expense
A22: Current tax | B22: 1910 | C22: 2179
A23: Deferred tax | B23: 225 | C23: -26
A24: Total tax expenses | B24: 2135 | C24: 2153
A25: Profit for the year | B25: 9130 | C25: 8175
A26: Other comprehensive income, net of taxes
A27: Items not reclassified to P&L - Remeasurement of defined benefit liability/asset (net of tax) | B27: -1 | C27: 24
A28: Items reclassified to P&L - Net change in FV of financial instruments through OCI (net of tax) | B28: 408 | C28: 349
A29: Net change in FV of cash flow hedge (net of tax) | B29: 65 | C29: -36
A30: Total other comprehensive income for the year, net of taxes | B30: 472 | C30: 337
A31: Total comprehensive income for the year | B31: 9602 | C31: 8512
A32: Earnings per equity share (par value Rs.10 each)
A33: Weighted average equity shares for computing basic and diluted EPS | B33: 483662163 | C33: 483662163
A34: Basic and diluted EPS (Rs.) | B34: 18.88 | C34: 16.9

Sheet CF 2020-21
A1: Wipro Enterprises (P) Limited (Standalone)
A2: Statement of Cash Flows
A3: Statement of Cash Flows for the year ended March 31, 2021 (Source: Annual Report 2020-21, p.61)
A4: (Amount Rs. in millions, unless otherwise stated)
A6: ` | B6: 2021 | C6: 2020
A7: A. Cash flows from operating activities
A8: Profit before tax | B8: 11264 | C8: 10328
A9: Depreciation and amortization | B9: 915 | C9: 956
A10: Interest on borrowings | B10: 762 | C10: 113
A11: Unrealized (gain)/loss on investments | B11: -1718 | C11: -658
A12: Dividend / interest income | B12: -2030 | C12: -1877
A13: Net (gain)/loss on sale of current investments | B13: -998 | C13: -915
A14: Net (gain)/loss on sale of associates | B14: -1762 | C14: -1185
A15: Net (gain)/loss on sale of PP&E and intangible assets | B15: -32 | C15: -2
A16: Allowance for doubtful receivables | B16: -5 | C16: 129
A17: Net foreign exchange differences on non-operating items | B17: -7 | C17: 11
A18: Working capital changes - Trade receivables | B18: -3137 | C18: 1351
A19: Working capital changes - Other assets | B19: 922 | C19: -1299
... A24: Net cash generated from operating activities | B24: 4670 | C24: 3728
A25: B. Cash flows from investing activities
A26: Acquisition of PP&E including capital advances | B26: -511 | C26: -851
A27: Proceeds from sale of PP&E | B27: 32 | C27: 2
A28: Investment in associates | B28: -105 | C28: -40
A29: Purchase of current investments | B29: -100542 | C29: -110863
A30: Purchase of non-current investments | B30: -150 | C30: -534
A31: Proceeds from sale/maturity of current investments | B31: 102688 | C31: 106374
A32: Proceeds from sale of investment in associates | B32: 1774 | C32: 1195
A33: Investment in subsidiaries | B33: -5398 | C33: -125
A34: Loan to subsidiaries | B34: -16448 | C34: 0
A35: Inter-corporate deposits placed | B35: -3518 | C35: 0
A36: Dividend / interest income received | B36: 1047 | C36: 1218
A37: Net cash used in investing activities | B37: -21131 | C37: -3624
A38: C. Cash flows from financing activities
A39: Interest paid on borrowings | B39: -742 | C39: -88
A40: Proceeds from borrowings / debentures | B40: 17677 | C40: 161
A41: Repayment of lease liabilities | B41: -77 | C41: -86
A42: Repayment of borrowings / loans | B42: -201 | C42: -310
A43: Net cash generated from/(used in) financing activities | B43: 16657 | C43: -323
A44: Net increase/(decrease) in cash and cash equivalents during the year | B44: 197 | C44: -220
A45: Cash and cash equivalents at the beginning of the year | B45: 1350 | C45: 1570
...

Sheet BS 2020-21
A1: Wipro Enterprises (P) Limited (Standalone)
A2: Balance Sheet
A3: Balance Sheet as at March 31, 2021 (Source: Annual Report 2020-21, WEL-Annual-Report-High-Res.pdf, p.58)
A4: (Amount Rs. in millions, unless otherwise stated)
A6: Particulars | B6: 2021 | C6: 2020
A7: ASSETS
A8: Non-current assets
A9: Property, plant and equipment | B9: 6172 | C9: 6866
A10: Capital work-in-progress | B10: 984 | C10: 578
A11: Right of use assets | B11: 853 | C11: 948
A12: Goodwill | B12: 497 | C12: 497
A13: Other intangible assets | B13: 766 | C13: 791
A14: Financial assets - Investments | B14: 30726 | C14: 24560
A15: Financial assets - Loans | B15: 16979 | C15: 483
A16: Financial assets - Other financial assets | B16: 18 | C16: 0
A17: Other non-current assets | B17: 112 | C17: 120
A18: Total non-current assets | B18: 57107 | C18: 34843
A19: Current assets
A20: Inventories | B20: 5778 | C20: 5846
A21: Financial assets - Investments | B21: 49294 | C21: 47238
A22: Financial assets - Trade receivables | B22: 7451 | C22: 4309
A23: Financial assets - Derivative instruments | B23: 95 | C23: 2
A24: Financial assets - Cash and cash equivalents | B24: 1547 | C24: 1350
A25: Financial assets - Loans | B25: 3956 | C25: 237 | F25: =SUM(C18,C29) -> 98321
A26: Financial assets - Other financial assets | B26: 737 | C26: 251
A27: Current tax assets (net) | B27: 243 | C27: 304
A28: Other assets | B28: 2832 | C28: 3941
A29: Total current assets | B29: 71933 | C29: 63478
A30: TOTAL ASSETS | B30: 129040 | C30: 98321
A31: EQUITY AND LIABILITIES
A32: Equity
A33: Share capital | B33: 4837 | C33: 4837
A34: Other equity | B34: 87753 | C34: 78152
A35: Total equity | B35: 92590 | C35: 82989
A36: Non-current liabilities
A37: Financial liabilities - Borrowings | B37: 17375 | C37: 1192
A38: Financial liabilities - Lease liabilities | B38: 61 | C38: 130
A39: Financial liabilities - Other financial liabilities | B39: 1023 | C39: 28
A40: Provisions | B40: 105 | C40: 183
A41: Deferred tax liabilities (net) | B41: 1488 | C41: 1224
...

Sheet Notes 2020-21
A1: Wipro Enterprises (P) Limited (Standalone)
A2: Notes to the Standalone Financial Statements (Selected Notes)
A3: Notes to the Standalone Financial Statements, year ended March 31, 2021 (Source: Annual Report 2020-21, pp.75-107)
A4: (Amount Rs. in millions, unless otherwise stated)
A6: Note 4. Property, plant and equipment - Net carrying value
B7: 2021 | C7: 2020
A8: Land | B8: 208 | C8: 310
A9: Buildings | B9: 1902 | C9: 2010
A10: Plant and Machinery | B10: 3921 | C10: 4396
A11: Furniture and Fixtures | B11: 43 | C11: 42
A12: Office Equipment | B12: 100 | C12: 102
A13: Vehicles | B13: 2 | C13: 7
A14: Total | B14: 6174 | C14: 6867
A15: (Total gross carrying value as at March 31, 2021: 14,469; accumulated depreciation: 8,297; March 31, 2020 gross: 14,619, accumulated depreciation: 7,753)
A17: Note 5. Right-of-use Assets - Net carrying value
B18: 2021 | C18: 2020
A19: Land | B19: 683 | C19: 715
A20: Buildings | B20: 152 | C20: 202
A21: Furniture and Fixtures | B21: 13 | C21: 21
A22: Vehicles | B22: 5 | C22: 9
A23: Total | B23: 853 | C23: 948
A25: Note 6. Goodwill and intangible assets - movement in Goodwill
B26: 2021 | C26: 2020
A27: Amount at the beginning of the year | B27: 497 | C27: 362
A28: Addition due to acquisition | B28: 0 | C28: 135
A29: Amount at the end of the year | B29: 497 | C29: 497
A30: Net block of other intangible assets: 766 (2021), 791 (2020) [Technical know-how 191/206; Brands, patents, trademarks & others 575/585]
A32: Note 7. Investments
B33: 2021 | C33: 2020
A34: Investment in subsidiaries - Equity shares | B34: 26467 | C34: 21142
A35: Investment in subsidiaries - Preference shares | B35: 1658 | C35: 562
A36: Investment in Associates - Equity shares | B36: 686 | C36: 668
A37: Investment in Associates - Compulsorily Convertible Preference Shares | B37: 315 | C37: 240
A38: Financial instruments at FVTPL - Liquid and short-term mutual funds | B38: 31340 | C38: 32108
A39: Financial instruments at FVTPL - Equity linked debentures | B39: 1558 | C39: 0
A40: Financial instruments at FVTPL - Convertible preference shares | B40: 150 | C40: 0
A41: Financial instruments at FVTOCI - Non-convertible debentures and bonds | B41: 16395 | C41: 15125
A42: Financial instruments at amortized cost - Tax saving bond | B42: 0 | C42: 5
A43: Financial instruments at amortized cost - Redeemable preference shares (net of impairment) | B43: 1450 | C43: 1955
A44: Total investments | B44: 80020 | C44: 71798
...

Sheet BS 2021-22
A1: Wipro Enterprises (P) Limited (Standalone)
A2: Balance Sheet
A3: Balance Sheet as at March 31, 2022 (Source: Annual Report 2021-22, Wipro-Enterprises-AR-2021-2022_LowRez-2.pdf, p.60). *2021 figures restated for merger, refer Note 46.
A4: (Amount Rs. in millions, unless otherwise stated)
A6: Particulars | B6: 2022 | C6: 2021*
A7: ASSETS
A8: Non-current assets
A9: Property, plant and equipment | B9: 8897 | C9: 6857
A10: Capital work-in-progress | B10: 1200 | C10: 2270
A11: Right of use assets | B11: 807 | C11: 853
A12: Goodwill | B12: 362 | C12: 497
A13: Other intangible assets | B13: 1101 | C13: 766
A14: Financial assets - Investments | B14: 32460 | C14: 30628
A15: Financial assets - Trade receivables | B15: 272 | C15: 250
A16: Financial assets - Loans | B16: 17133 | C16: 15247
A17: Financial assets - Other financial assets | B17: 58 | C17: 26
A18: Other assets | B18: 135 | C18: 388
A19: Total non-current assets | B19: 62425 | C19: 57782
A20: Current assets
A21: Inventories | B21: 8616 | C21: 5896
A22: Financial assets - Investments | B22: 54972 | C22: 49403
A23: Financial assets - Trade receivables | B23: 6017 | C23: 7201
A24: Financial assets - Derivative instruments | B24: 304 | C24: 95
A25: Financial assets - Cash and cash equivalents | B25: 2742 | C25: 1654
A26: Financial assets - Loans | B26: 251 | C26: 3518
A27: Financial assets - Other financial assets | B27: 1638 | C27: 897
A28: Current tax assets (net) | B28: 720 | C28: 243
A29: Other assets | B29: 2914 | C29: 3213
A30: Total current assets | B30: 78174 | C30: 72120
A31: TOTAL ASSETS | B31: 140599 | C31: 129902
A32: EQUITY AND LIABILITIES
A33: Equity
A34: Share capital | B34: 4837 | C34: 4837
A35: Other equity | B35: 96046 | C35: 88351
A36: Total equity | B36: 100883 | C36: 93188
A37: Non-current liabilities
A38: Financial liabilities - Borrowings | B38: 18967 | C38: 17375
A39: Financial liabilities - Lease liabilities | B39: 32 | C39: 61
A40: Financial liabilities - Other financial liabilities | B40: 1103 | C40: 1023
A41: Provisions | B41: 138 | C41: 105
...

Sheet PL 2021-22
A1: Wipro Enterprises (P) Limited (Standalone)
A2: Statement of Profit and Loss
A3: Statement of Profit and Loss for the year ended March 31, 2022 (Source: Annual Report 2021-22, p.61). *2021 figures restated for merger, refer Note 46.
A4: (Amount Rs. in millions, unless otherwise stated)
A6: Particulars | B6: 2022 | C6: 2021*
A7: REVENUE
A8: Revenue from operations | B8: 57884 | C8: 50849
A9: Other income | B9: 5900 | C9: 6895
A10: Total income | B10: 63784 | C10: 57743
A11: EXPENSES
A12: Cost of materials consumed | B12: 19806 | C12: 19375
A13: Purchases of stock-in-trade | B13: 16070 | C13: 8407
A14: Changes in inventories of finished products, WIP and stock-in-trade | B14: -1762 | C14: 313
A15: Employee benefits expense | B15: 4944 | C15: 4556
A16: Finance costs | B16: 1129 | C16: 784
A17: Depreciation and amortisation expense | B17: 990 | C17: 940
A18: Other expenses | B18: 12035 | C18: 11273
A19: Total expenses | B19: 53210 | C19: 45647
A20: Profit before tax | B20: 10574 | C20: 12096
A21: Tax expense
A22: Current tax | B22: 2411 | C22: 2125
A23: Deferred tax | B23: -14 | C23: 237
A24: Total tax expenses | B24: 2397 | C24: 2362
A25: Profit for the year | B25: 8177 | C25: 9734
A26: Other comprehensive income, net of taxes
A27: Remeasurement of defined benefit liability/asset (net of tax) | B27: -6 | C27: -1
A28: Net change in FV of financial instruments through OCI (net of tax) | B28: -624 | C28: 408
A29: Net change in FV of cash flow hedge (net of tax) | B29: 147 | C29: 65
A30: Total other comprehensive income for the year, net of taxes | B30: -483 | C30: 472
A31: Total comprehensive income for the year | B31: 7694 | C31: 10206
A32: Earnings per equity share (par value Rs.10 each)
A33: Weighted average equity shares for computing basic and diluted EPS | B33: 483662163 | C33: 483662163
A34: Basic and diluted EPS (Rs.) | B34: 16.91 | C34: 20.13

Sheet CF 2021-22
A1: Wipro Enterprises (P) Limited (Standalone)
A2: Statement of Cash Flows
A3: Statement of Cash Flows for the year ended March 31, 2022 (Source: Annual Report 2021-22, p.63). *2021 figures restated for merger, refer Note 46.
A4: (Amount Rs. in millions, unless otherwise stated)
A6: Particulars | B6: 2022 | C6: 2021*
A7: A. Cash flows from operating activities
A8: Profit before tax | B8: 10574 | C8: 12096
A9: Depreciation and amortization | B9: 990 | C9: 940
A10: Interest on borrowings | B10: 1129 | C10: 784
A11: Unrealized (gain)/loss on investments | B11: 189 | C11: -1719
A12: Dividend / interest income | B12: -2447 | C12: -2016
A13: Net (gain)/loss on sale of current investments | B13: -2938 | C13: -1001
A14: Net (gain)/loss on sale of associates | B14: 0 | C14: -1762
A15: Net (gain)/loss on sale of PP&E and intangible assets | B15: -31 | C15: -32
A16: Allowance for doubtful receivables | B16: -19 | C16: -5
A17: Net foreign exchange differences on non-operating items | B17: -54 | C17: -6
A18: Working capital changes - Trade receivables | B18: 1181 | C18: -3246
A19: Working capital changes - Other assets | B19: -397 | C19: 953
... A24: Net cash generated from operating activities | B24: 3121 | C24: 5377
A25: B. Cash flows from investing activities
A26: Acquisition of PP&E including capital advances | B26: -2192 | C26: -1601
A27: Proceeds from sale of PP&E | B27: 31 | C27: 32
A28: Investment in associates | B28: -255 | C28: -105
A29: Purchase of current investments | B29: -90543 | C29: -101201
A30: Purchase of non-current investments | B30: -75 | C30: -150
A31: Proceeds from sale/maturity of current investments | B31: 87684 | C31: 103271
A32: Proceeds from sale of investment in associates | B32: 450 | C32: 1774
A33: Investment in subsidiaries | B33: -1659 | C33: -5348
A34: Loan to subsidiaries | B34: -2136 | C34: -16448
A35: Inter-corporate deposits placed | B35: 3518 | C35: -3518
A36: Dividend / interest income received | B36: 2077 | C36: 1047
A37: Net cash used in investing activities | B37: -3100 | C37: -22247
A38: C. Cash flows from financing activities
A39: Interest paid on borrowings | B39: -1114 | C39: -778
A40: Proceeds from borrowings / debentures | B40: 11326 | C40: 19407
A41: Repayment of lease liabilities | B41: -56 | C41: -77
A42: Repayment of borrowings / loans | B42: -9090 | C42: -1407
A43: Net cash generated from/(used in) financing activities | B43: 1066 | C43: 17145
A44: Net increase/(decrease) in cash and cash equivalents during the year | B44: 1088 | C44: 275
A45: Cash and cash equivalents at the beginning of the year | B45: 1654 | C45: 1379
...

Sheet _Combined Balance Sheet
B2: Particulars | C2: 2020 | D2: 2021
B3: ASSETS
B4: Non-current assets
B5: Property, plant and equipment | C5: 6866 | D5: =IFERROR(INDEX('BS 2021-22'!C9:C18,MATCH('_Combined Balance Sheet'!B5,'BS 2021-22'!A9:A19,0)),0) -> 6857
B6: Capital work-in-progress | C6: 578 | D6: =IFERROR(INDEX('BS 2021-22'!C10:C19,MATCH('_Combined Balance Sheet'!B6,'BS 2021-22'!A10:A20,0)),0) -> 2270
B7: Right of use assets | C7: 948 | D7: =IFERROR(INDEX('BS 2021-22'!C11:C20,MATCH('_Combined Balance Sheet'!B7,'BS 2021-22'!A11:A21,0)),0) -> 853
B8: Goodwill | C8: 497 | D8: =IFERROR(INDEX('BS 2021-22'!C12:C21,MATCH('_Combined Balance Sheet'!B8,'BS 2021-22'!A12:A22,0)),0) -> 497
B9: Other intangible assets | C9: 791 | D9: =IFERROR(INDEX('BS 2021-22'!C13:C22,MATCH('_Combined Balance Sheet'!B9,'BS 2021-22'!A13:A23,0)),0) -> 766
B10: Financial assets - Investments | C10: 24560 | D10: =IFERROR(INDEX('BS 2021-22'!C14:C23,MATCH('_Combined Balance Sheet'!B10,'BS 2021-22'!A14:A24,0)),0) -> 30628
B11: Financial assets - Loans | C11: 483 | D11: =IFERROR(INDEX('BS 2021-22'!C15:C24,MATCH('_Combined Balance Sheet'!B11,'BS 2021-22'!A15:A25,0)),0) -> 15247
B12: Financial assets - Other financial assets | C12: 0 | D12: =IFERROR(INDEX('BS 2021-22'!C16:C25,MATCH('_Combined Balance Sheet'!B12,'BS 2021-22'!A16:A26,0)),0) -> 26
B13: Other non-current assets | C13: 120 | D13: =IFERROR(INDEX('BS 2021-22'!C17:C26,MATCH('_Combined Balance Sheet'!B13,'BS 2021-22'!A17:A27,0)),0) -> 0
B14: Total non-current assets | C14: 34843 | D14: =IFERROR(INDEX('BS 2021-22'!C18:C27,MATCH('_Combined Balance Sheet'!B14,'BS 2021-22'!A18:A28,0)),0) -> 57782
B15: Current assets
B16: Inventories | C16: 5846 | D16: =IFERROR(INDEX('BS 2021-22'!C21:C31,MATCH('_Combined Balance Sheet'!B16,'BS 2021-22'!A21:A31,0)),0) -> 5896
B17: Financial assets - Investments | C17: 47238 | D17: =IFERROR(INDEX('BS 2021-22'!C22:C32,MATCH('_Combined Balance Sheet'!B17,'BS 2021-22'!A22:A32,0)),0) -> 49403
B18: Financial assets - Trade receivables | C18: 4309 | D18: =IFERROR(INDEX('BS 2021-22'!C23:C33,MATCH('_Combined Balance Sheet'!B18,'BS 2021-22'!A23:A33,0)),0) -> 7201
B19: Financial assets - Derivative instruments | C19: 2 | D19: =IFERROR(INDEX('BS 2021-22'!C24:C34,MATCH('_Combined Balance Sheet'!B19,'BS 2021-22'!A24:A34,0)),0) -> 95
B20: Financial assets - Cash and cash equivalents | C20: 1350 | D20: =IFERROR(INDEX('BS 2021-22'!C25:C35,MATCH('_Combined Balance Sheet'!B20,'BS 2021-22'!A25:A35,0)),0) -> 1654
B21: Financial assets - Loans | C21: 237 | D21: =IFERROR(INDEX('BS 2021-22'!C26:C36,MATCH('_Combined Balance Sheet'!B21,'BS 2021-22'!A26:A36,0)),0) -> 3518
B22: Financial assets - Other financial assets | C22: 251 | D22: =IFERROR(INDEX('BS 2021-22'!C27:C37,MATCH('_Combined Balance Sheet'!B22,'BS 2021-22'!A27:A37,0)),0) -> 897
B23: Current tax assets (net) | C23: 304 | D23: =IFERROR(INDEX('BS 2021-22'!C28:C38,MATCH('_Combined Balance Sheet'!B23,'BS 2021-22'!A28:A38,0)),0) -> 243
B24: Other assets | C24: 3941 | D24: =IFERROR(INDEX('BS 2021-22'!C29:C39,MATCH('_Combined Balance Sheet'!B24,'BS 2021-22'!A29:A39,0)),0) -> 3213
B25: Total current assets | C25: 63478 | D25: =IFERROR(INDEX('BS 2021-22'!C30:C40,MATCH('_Combined Balance Sheet'!B25,'BS 2021-22'!A30:A40,0)),0) -> 72120
B26: TOTAL ASSETS | C26: 98321 | D26: =IFERROR(INDEX('BS 2021-22'!C31:C41,MATCH('_Combined Balance Sheet'!B26,'BS 2021-22'!A31:A41,0)),0) -> 129902
B27: EQUITY AND LIABILITIES
B28: Equity
B29: Share capital | C29: 4837 | D29: =IFERROR(INDEX('BS 2021-22'!C34:C36,MATCH('_Combined Balance Sheet'!B29,'BS 2021-22'!A34:A35,0)),0) -> 4837
B30: Other equity | C30: 78152 | D30: =IFERROR(INDEX('BS 2021-22'!C35:C37,MATCH('_Combined Balance Sheet'!B30,'BS 2021-22'!A35:A36,0)),0) -> 88351
B31: Total equity | C31: 82989
B32: Non-current liabilities
B33: Financial liabilities - Borrowings | C33: 1192 | D33: =IFERROR(INDEX('BS 2020-21'!C37:C42,MATCH('_Combined Balance Sheet'!B33,'BS 2020-21'!A37:A42,0)),0) -> 1192
B34: Financial liabilities - Lease liabilities | C34: 130 | D34: =IFERROR(INDEX('BS 2020-21'!C38:C43,MATCH('_Combined Balance Sheet'!B34,'BS 2020-21'!A38:A43,0)),0) -> 130
B35: Financial liabilities - Other financial liabilities | C35: 28 | D35: =IFERROR(INDEX('BS 2020-21'!C39:C44,MATCH('_Combined Balance Sheet'!B35,'BS 2020-21'!A39:A44,0)),0) -> 28
B36: Provisions | C36: 183 | D36: =IFERROR(INDEX('BS 2020-21'!C40:C45,MATCH('_Combined Balance Sheet'!B36,'BS 2020-21'!A40:A45,0)),0) -> 183
B37: Deferred tax liabilities (net) | C37: 1224 | D37: =IFERROR(INDEX('BS 2020-21'!C41:C46,MATCH('_Combined Balance Sheet'!B37,'BS 2020-21'!A41:A46,0)),0) -> 1224
B38: Total non-current liabilities | C38: 2757 | D38: =IFERROR(INDEX('BS 2020-21'!C42:C47,MATCH('_Combined Balance Sheet'!B38,'BS 2020-21'!A42:A47,0)),0) -> 2757
B39: Current assets
B40: Financial liabilities - Borrowings | C40: 761 | D40: =IFERROR(INDEX('BS 2020-21'!C44:C55,MATCH('_Combined Balance Sheet'!B40,'BS 2020-21'!A44:A55,0)),0) -> 761
B41: Financial liabilities - Lease liabilities | C41: 118 | D41: =IFERROR(INDEX('BS 2020-21'!C45:C56,MATCH('_Combined Balance Sheet'!B41,'BS 2020-21'!A45:A56,0)),0) -> 118
...

Sheet Notes 2021-22
A1: Wipro Enterprises (P) Limited (Standalone)
A2: Notes to the Standalone Financial Statements (Selected Notes)
A3: Notes to the Standalone Financial Statements, year ended March 31, 2022 (Source: Annual Report 2021-22, pp.75-110)
A4: (Amount Rs. in millions, unless otherwise stated)
A6: Note 4. Property, plant and equipment - Net carrying value (*restated for merger)
B7: 2022 | C7: 2021*
A8: Land | B8: 491 | C8: 208
A9: Buildings | B9: 3708 | C9: 2137
A10: Plant and Machinery | B10: 4525 | C10: 4366
A11: Furniture and Fixtures | B11: 70 | C11: 44
A12: Office Equipment | B12: 100 | C12: 102
A13: Vehicles | B13: 3 | C13: 1
A14: Total | B14: 8897 | C14: 6858
A16: Note 5. Capital work-in-progress - ageing (Projects in progress)
B17: 2022 | C17: 2021*
A18: Less than 1 year | B18: 756 | C18: 1769
A19: 1-2 years | B19: 419 | C19: 281
A20: 2-3 years | B20: 22 | C20: 103
A21: More than 3 years | B21: 3 | C21: 117
A22: Total CWIP | B22: 1200 | C22: 2270
A24: Note 6. Right-of-use assets - Net carrying value
B25: 2022 | C25: 2021*
A26: Land | B26: 675 | C26: 683
A27: Buildings | B27: 123 | C27: 152
A28: Furniture and Fixtures | B28: 7 | C28: 13
A29: Vehicles | B29: 4 | C29: 6
A30: Total | B30: 807 | C30: 853
A32: Note 7. Goodwill and intangible assets - movement in Goodwill
B33: 2022 | C33: 2021*
A34: Amount at the beginning of the year | B34: 497 | C34: 497
A35: Deletion during the year (sale of automation division) | B35: -135 | C35: 0
A36: Amount at the end of the year | B36: 362 | C36: 497
A37: Net block of other intangible assets: 1,101 (2022), 766 (2021) [Technical know-how 177/191; Brands, patents, trademarks & others 924/575]
A39: Note 8. Investments
B40: 2022 | C40: 2021*
A41: Investments in subsidiaries - Equity shares | B41: 28071 | C41: 26369
A42: Investments in subsidiaries - Preference shares | B42: 1658 | C42: 1658
A43: Investments in Associates - Equity shares | B43: 741 | C43: 686
A44: Investments in Associates - Compulsorily convertible preference shares | B44: 515 | C44: 315
A45: FVTPL - Liquid and short-term mutual funds | B45: 34618 | C45: 31448
...

Sheet BS 2022-23
A1: Wipro Enterprises (P) Limited (Standalone)
A2: Balance Sheet
A3: Balance Sheet as at March 31, 2023 (Source: Annual Report 2022-23, New-Annual_Report_Wipro_Enterprises_2022-2023.pdf, p.72)
A4: (Amount Rs. in millions, unless otherwise stated)
A6: Particulars | B6: 2023 | C6: 2022
A7: ASSETS
A8: Non-current assets
A9: Property, plant and equipment | B9: 9793 | C9: 8897
A10: Capital work-in-progress | B10: 304 | C10: 1200
A11: Right of use assets | B11: 800 | C11: 807
A12: Goodwill | B12: 362 | C12: 362
A13: Other intangible assets | B13: 1723 | C13: 1101
A14: Financial assets - Investments | B14: 33415 | C14: 32785
A15: Financial assets - Trade receivables | B15: 99 | C15: 272
A16: Financial assets - Derivative instruments | B16: 1 | C16: 0 | G16: =B9 -> 9793
A17: Financial assets - Loans | B17: 15048 | C17: 17366 | G17: =SUM(B10) -> 304
A18: Financial assets - Other financial assets | B18: 4 | C18: 58 | G18: =SUM(C14) -> 32785
A19: Non current tax assets (net) | B19: 661 | C19: 720 | G19: =SUM(B11:B13,B15:B20) -> 19592
A20: Other assets | B20: 894 | C20: 839
A21: Total non-current assets | B21: 63104 | C21: 64407
A22: Current assets
A23: Inventories | B23: 8069 | C23: 8616
A24: Financial assets - Investments | B24: 67114 | C24: 54972
A25: Financial assets - Trade receivables | B25: 6799 | C25: 5784
A26: Financial assets - Derivative instruments | B26: 0 | C26: 9
A27: Financial assets - Cash and cash equivalents | B27: 1597 | C27: 2742
A28: Financial assets - Loans | B28: 5324 | C28: 251
A29: Financial assets - Other financial assets | B29: 2017 | C29: 1313
A30: Other assets | B30: 1764 | C30: 2210
A31: Assets held for sale | B31: 53 | C31: 0
A32: Total current assets | B32: 92737 | C32: 75897
A33: TOTAL ASSETS | B33: 155841 | C33: 140304
A34: EQUITY AND LIABILITIES
A35: Equity
A36: Share capital | B36: 4837 | C36: 4837
A37: Other equity | B37: 106557 | C37: 96046
A38: Total equity | B38: 111394 | C38: 100883
A39: Non-current liabilities
A40: Financial liabilities - Borrowings | B40: 14985 | C40: 18967
A41: Financial liabilities - Lease liabilities | B41: 22 | C41: 32
...

Sheet PL 2022-23
A1: Wipro Enterprises (P) Limited (Standalone)
A2: Statement of Profit and Loss
A3: Statement of Profit and Loss for the year ended March 31, 2023 (Source: Annual Report 2022-23, p.73)
A4: (Amount Rs. in millions, unless otherwise stated)
A6: Particulars | B6: 2023 | C6: 2022
A7: REVENUE
A8: Revenue from operations | B8: 70052 | C8: 57884
A9: Other income | B9: 7572 | C9: 5711
A10: Total income | B10: 77624 | C10: 63595
A11: EXPENSES
A12: Cost of materials consumed | B12: 37573 | C12: 29030
A13: Purchases of stock-in-trade | B13: 3163 | C13: 6846
A14: Changes in inventories of finished products, WIP and stock-in-trade | B14: 594 | C14: -1762
A15: Employee benefits expense | B15: 5585 | C15: 4944
A16: Finance costs | B16: 1254 | C16: 1129
A17: Depreciation and amortisation expense | B17: 1151 | C17: 990
A18: Other expenses | B18: 15329 | C18: 11844
A19: Total Expenses | B19: 64649 | C19: 53021
A20: Profit before tax | B20: 12975 | C20: 10574
A21: Tax expense
A22: Current tax | B22: 2501 | C22: 2411
A23: Deferred tax | B23: -214 | C23: -14
A24: Total tax expenses | B24: 2287 | C24: 2397
A25: Profit for the year | B25: 10688 | C25: 8177
A26: Other comprehensive income, net of taxes
A27: Remeasurement of defined benefit liability/asset (net of tax) | B27: 9 | C27: -6
A28: Net change in FV of financial instruments through OCI (net of tax) | B28: -213 | C28: -624
A29: Net change in FV of cash flow hedge (net of tax) | B29: 27 | C29: 147
A30: Total other comprehensive income for the year, net of taxes | B30: -177 | C30: -483
A31: Total comprehensive income for the year | B31: 10511 | C31: 7694
A32: Earnings per equity share (par value Rs.10 each)
A33: Weighted average equity shares for computing basic and diluted EPS | B33: 483662163 | C33: 483662163
A34: Basic and diluted EPS (Rs.) | B34: 22.1 | C34: 16.91

Sheet CF 2022-23
A1: Wipro Enterprises (P) Limited (Standalone)
A2: Statement of Cash Flows
A3: Statement of Cash Flows for the year ended March 31, 2023 (Source: Annual Report 2022-23, p.75)
A4: (Amount Rs. in millions, unless otherwise stated)
A6: Particulars | B6: 2023 | C6: 2022
A7: A. Cash flows from operating activities
A8: Profit before tax | B8: 12975 | C8: 10574
A9: Depreciation and amortization | B9: 1151 | C9: 990
A10: Interest on borrowings | B10: 1254 | C10: 1129
A11: Dividend / interest income | B11: -3258 | C11: -2447
A12: Net (gain)/loss on sale of current investments | B12: -1397 | C12: -2749
A13: Net (gain)/loss on sale of associates | B13: -2206 | C13: 0
A14: Net (gain)/loss on sale of PP&E and intangible assets | B14: -13 | C14: -31
A15: Allowance for doubtful receivables | B15: 102 | C15: -19
A16: Net foreign exchange differences on non-operating items | B16: -116 | C16: -54
A17: Working capital changes - Trade receivables | B17: -595 | C17: 1181
A18: Working capital changes - Other assets | B18: 73 | C18: -397
A19: Working capital changes - Inventories | B19: 547 | C19: -2720
... A23: Net cash generated from operating activities | B23: 6874 | C23: 3121
A24: B. Cash flows from investing activities
A25: Acquisition of PP&E including capital advances | B25: -1662 | C25: -2158
A26: Proceeds from sale of PP&E | B26: 13 | C26: 31
A27: Investment in associates | B27: -5 | C27: -255
A28: Purchase of current investments | B28: -104256 | C28: -90543
A29: Purchase of non-current investments | B29: -335 | C29: -75
A30: Proceeds from sale/maturity of current investments | B30: 95771 | C30: 87684
A31: Proceeds from sale of investment in associates | B31: 2217 | C31: 450
A32: Investment in subsidiaries | B32: -572 | C32: -1659
A33: Loan to subsidiaries | B33: -3313 | C33: -2136
A34: Inter-corporate deposits placed | B34: 0 | C34: 3518
A35: Dividend / interest income received | B35: 2460 | C35: 2077
A36: Net cash used in investing activities | B36: -9682 | C36: -3066
A37: C. Cash flows from financing activities
A38: Interest paid on borrowings | B38: -1242 | C38: -1114
A39: Proceeds from borrowings / debentures | B39: 5520 | C39: 11326
A40: Repayment of lease liabilities | B40: -101 | C40: -90
A41: Repayment of borrowings / loans | B41: -2514 | C41: -9090
A42: Net cash generated from/(used in) financing activities | B42: 1663 | C42: 1032
A43: Net increase/(decrease) in cash and cash equivalents during the year | B43: -1145 | C43: 1088
A44: Cash and cash equivalents at the beginning of the year | B44: 2742 | C44: 1654
...

Sheet Notes 2022-23
A1: Wipro Enterprises (P) Limited (Standalone)
A2: Notes to the Standalone Financial Statements (Selected Notes)
A3: Notes to the Standalone Financial Statements, year ended March 31, 2023 (Source: Annual Report 2022-23, pp.90-136)
A4: (Amount Rs. in millions, unless otherwise stated)
A6: Note 4. Property, plant and equipment - Net carrying value
B7: 2023 | C7: 2022
A8: Land | B8: 425 | C8: 491
A9: Buildings | B9: 3803 | C9: 3708
A10: Plant and Machinery | B10: 5287 | C10: 4525
A11: Furniture and Fixtures | B11: 149 | C11: 70
A12: Office Equipment | B12: 122 | C12: 100
A13: Vehicles | B13: 7 | C13: 3
A14: Total | B14: 9793 | C14: 8897
A16: Note 5. Capital work-in-progress - ageing (Projects in progress)
B17: 2023 | C17: 2022
A18: Less than 1 year | B18: 284 | C18: 756
A19: 1-2 years | B19: 16 | C19: 419
A20: 2-3 years | B20: 4 | C20: 22
A21: More than 3 years | B21: 0 | C21: 3
A22: Total CWIP | B22: 304 | C22: 1200
A24: Note 6. Right-of-use assets - Net carrying value
B25: 2023 | C25: 2022
A26: Land | B26: 699 | C26: 675
A27: Buildings | B27: 96 | C27: 123
A28: Furniture and Fixtures | B28: 1 | C28: 7
A29: Vehicles | B29: 4 | C29: 2
A30: Total | B30: 800 | C30: 807
A32: Note 7. Goodwill and intangible assets - movement in Goodwill
B33: 2023 | C33: 2022
A34: Amount at the beginning of the year | B34: 362 | C34: 497
A35: Deletion during the year | B35: 0 | C35: -135
A36: Amount at the end of the year | B36: 362 | C36: 362
A37: Net block of other intangible assets: 1,723 (2023), 1,101 (2022) [Technical know-how 157/177; Brands, patents, trademarks & others 1,566/924]
A39: Note 8. Investment
B40: 2023 | C40: 2022
A41: Non-current - Investments in subsidiaries - Equity shares | B41: 28133 | C41: 28071
A42: Non-current - Investments in subsidiaries - Redeemable preference shares | B42: 2140 | C42: 1983
A43: Non-current - Investments in Associates - Equity shares | B43: 735 | C43: 741
A44: Non-current - Investments in Associates - Compulsorily convertible preference shares | B44: 595 | C44: 515
A45: Non-current - FVTPL - Compulsorily convertible preference shares | B45: 604 | C45: 524
...

Sheet BS 2023-24
A1: Wipro Enterprises (P) Limited (Standalone)
A2: Balance Sheet
A3: Balance Sheet as at March 31, 2024 (Source: Annual Report 2023-24, Annual-Report-2023-24v1.pdf, p.82)
A4: (Amount Rs. in millions, unless otherwise stated)
A6: Particulars | B6: 2024 | C6: 2023
A7: ASSETS
A8: Non-current assets
A9: Property, plant and equipment | B9: 9724 | C9: 9793
A10: Capital work-in-progress | B10: 141 | C10: 195
A11: Intangible asset under development | B11: 140 | C11: 109
A12: Right of use assets | B12: 810 | C12: 800
A13: Goodwill | B13: 1268 | C13: 362
A14: Other intangible assets | B14: 3983 | C14: 1723
A15: Financial assets - Investments | B15: 33176 | C15: 33415
A16: Financial assets - Trade receivables | B16: 45 | C16: 99
A17: Financial assets - Derivative assets | B17: 0 | C17: 1
A18: Financial assets - Loans | B18: 18265 | C18: 15048
A19: Financial assets - Other financial assets | B19: 106 | C19: 4
A20: Non current tax assets (net) | B20: 788 | C20: 661
... A22: Total non-current assets | B22: 69586 | C22: 63104
A23: Current assets
A24: Inventories | B24: 6402 | C24: 8069
A25: Financial assets - Investments | B25: 73332 | C25: 67114
A26: Financial assets - Trade receivables | B26: 7345 | C26: 6799
A27: Financial assets - Derivative assets | B27: 5 | C27: 0
A28: Financial assets - Cash and cash equivalents | B28: 3309 | C28: 1597
A29: Financial assets - Loans | B29: 2727 | C29: 5324
A30: Financial assets - Other financial assets | B30: 1319 | C30: 2017
A31: Other assets | B31: 2063 | C31: 1764
A32: Assets held for sale | B32: 53 | C32: 53
A33: Total current assets | B33: 96555 | C33: 92737
A34: TOTAL ASSETS | B34: 166141 | C34: 155841
A35: EQUITY AND LIABILITIES
A36: Equity
A37: Share capital | B37: 4837 | C37: 4837
A38: Other equity | B38: 119159 | C38: 106557
A39: Total equity | B39: 123996 | C39: 111394
A40: Non-current liabilities
A41: Financial liabilities - Borrowings | B41: 11967 | C41: 14985
A42: Financial liabilities - Lease liabilities | B42: 79 | C42: 22
...

Sheet PL 2023-24
A1: Wipro Enterprises (P) Limited (Standalone)
A2: Statement of Profit and Loss
A3: Statement of Profit and Loss for the year ended March 31, 2024 (Source: Annual Report 2023-24, p.83)
A4: (Amount Rs. in millions, unless otherwise stated)
A6: Particulars | B6: 2024 | C6: 2023
A7: REVENUE
A8: Revenue from operations | B8: 71763 | C8: 70052
A9: Other income | B9: 9583 | C9: 7531
A10: Total income | B10: 81346 | C10: 77583
A11: EXPENSES
A12: Cost of materials consumed | B12: 38297 | C12: 37573
A13: Purchases of stock-in-trade | B13: 530 | C13: 3163
A14: Changes in inventories of finished products, WIP and stock-in-trade | B14: 697 | C14: 594
A15: Employee benefits expense | B15: 6264 | C15: 5585
A16: Finance costs | B16: 1478 | C16: 1213
A17: Depreciation and amortisation expense | B17: 1830 | C17: 1151
A18: Other expenses | B18: 16243 | C18: 15329
A19: Total Expenses | B19: 65339 | C19: 64608
A20: Profit before tax | B20: 16007 | C20: 12975
A21: Tax expense
A22: Current tax | B22: 2766 | C22: 2501
A23: Deferred tax | B23: 609 | C23: -214
A24: Total tax expenses | B24: 3375 | C24: 2287
A25: Profit for the year | B25: 12632 | C25: 10688
A26: Other comprehensive income, net of taxes
A27: Remeasurement of defined benefit liability/asset (net of tax) | B27: -85 | C27: 9
A28: Net change in FV of financial instruments through OCI (net of tax) | B28: 122 | C28: -213
A29: Net change in FV of cash flow hedge (net of tax) | B29: -67 | C29: 27
A30: Total other comprehensive income for the year, net of taxes | B30: -30 | C30: -177
A31: Total comprehensive income for the year | B31: 12602 | C31: 10511
A32: Earnings per equity share (par value Rs.10 each)
A33: Weighted average equity shares for computing basic and diluted EPS | B33: 483662163 | C33: 483662163
A34: Basic and diluted EPS (Rs.) | B34: 26.12 | C34: 22.1

Sheet CF 2023-24
A1: Wipro Enterprises (P) Limited (Standalone)
A2: Statement of Cash Flows
A3: Statement of Cash Flows for the year ended March 31, 2024 (Source: Annual Report 2023-24, p.85)
A4: (Amount Rs. in millions, unless otherwise stated)
A6: Particulars | B6: 2024 | C6: 2023
A7: A. Cash flows from operating activities
A8: Profit before tax | B8: 16007 | C8: 12975
A9: Depreciation and amortization | B9: 1830 | C9: 1151
A10: Interest on borrowings | B10: 1478 | C10: 1254
A11: Changes in fair value of investment accounted at FVTPL | B11: -174 | C11: 0
A12: Dividend / interest income | B12: -4008 | C12: -3258
A13: Net (gain)/loss on sale of current investments | B13: -2729 | C13: -1397
A14: Net (gain)/loss on sale of associates | B14: -1392 | C14: -2206
A15: Net (gain)/loss on sale of PP&E and intangible assets | B15: -1 | C15: -13
A16: Change in fair value of contingent consideration | B16: -614 | C16: 0
A17: Allowance for doubtful receivables | B17: 41 | C17: 102
A18: Net foreign exchange differences on non-operating items | B18: -93 | C18: -116
A19: Working capital changes - Trade receivables | B19: -439 | C19: -595
... A25: Net cash generated from operating activities | B25: 8621 | C25: 6874
A26: B. Cash flows from investing activities
A27: Acquisition of PP&E including capital advances | B27: -861 | C27: -1428
A28: Proceeds from sale of PP&E | B28: 28 | C28: 13
A29: Investment in associates | B29: -150 | C29: -5
A30: Purchase of investments | B30: -75423 | C30: -104591
A31: Proceeds from sale/maturity of investments | B31: 72957 | C31: 95771
A32: Proceeds from sale of investment in associates | B32: 1495 | C32: 2217
A33: Payment for business acquisitions, net of cash acquired | B33: -3388 | C33: 0
A34: Investment in subsidiaries | B34: 0 | C34: -572
A35: Loan to subsidiaries | B35: -620 | C35: -3313
A36: Amount received on liquidation of subsidiary | B36: 48 | C36: 0
A37: Interest income received | B37: 3235 | C37: 2389
A38: Dividend received | B38: 70 | C38: 71
A39: Net cash used in investing activities | B39: -2609 | C39: -9448
A40: C. Cash flows from financing activities
A41: Interest paid on borrowings | B41: -1608 | C41: -1242
A42: Payment of contingent consideration | B42: -733 | C42: -234
A43: Proceeds from borrowings | B43: 7481 | C43: 11174
A44: Payment of lease liabilities | B44: -123 | C44: -101
A45: Repayment of borrowings | B45: -9317 | C45: -8168
A46: Net cash generated from/(used in) financing activities | B46: -4300 | C46: 1429
...

Sheet Notes 2023-24
A1: Wipro Enterprises (P) Limited (Standalone)
A2: Notes to the Standalone Financial Statements (Selected Notes)
A3: Notes to the Standalone Financial Statements, year ended March 31, 2024 (Source: Annual Report 2023-24, pp.101-143)
A4: (Amount Rs. in millions, unless otherwise stated)
A6: Note 4. Property, plant and equipment - Net carrying value
B7: 2024 | C7: 2023
A8: Land | B8: 527 | C8: 425
A9: Buildings | B9: 3816 | C9: 3803
A10: Plant and Machinery | B10: 5085 | C10: 5287
A11: Furniture and Fixtures | B11: 152 | C11: 149
A12: Office Equipment | B12: 132 | C12: 122
A13: Vehicles | B13: 12 | C13: 7
A14: Total | B14: 9724 | C14: 9793
A16: Note 5. Capital work-in-progress - ageing (Projects in progress)
B17: 2024 | C17: 2023
A18: Less than 1 year | B18: 119 | C18: 172
A19: 1-2 years | B19: 15 | C19: 16
A20: 2-3 years | B20: 0 | C20: 7
A21: More than 3 years | B21: 7 | C21: 0
A22: Total CWIP | B22: 141 | C22: 195
A23: Intangible asset under development: 140 (2024), 109 (2023)
A25: Note 6. Right-of-use assets - Net carrying value
B26: 2024 | C26: 2023
A27: Land | B27: 714 | C27: 699
A28: Buildings | B28: 62 | C28: 96
A29: Furniture and Fixtures | B29: 31 | C29: 1
A30: Vehicles | B30: 3 | C30: 4
A31: Total | B31: 810 | C31: 800
A33: Note 7. Goodwill and intangible assets - movement in Goodwill
B34: 2024 | C34: 2023
A35: Amount at the beginning of the year | B35: 362 | C35: 362
A36: Addition during the year (business combinations) | B36: 906 | C36: 0
A37: Amount at the end of the year | B37: 1268 | C37: 362
A38: Net block of other intangible assets: 3,983 (2024), 1,723 (2023). Impairment charge of 568 recognized in FY2024 on brand/distribution intangibles.
A40: Note 8. Investment
B41: 2024 | C41: 2023
A42: Non-current - Investments in subsidiaries - Equity shares | B42: 28085 | C42: 28133
A43: Non-current - Investments in subsidiaries - Redeemable preference shares | B43: 2170 | C43: 2140
A44: Non-current - Investments in Associates - Equity Instruments | B44: 729 | C44: 735
A45: Non-current - Investments in Associates - Compulsorily convertible preference shares | B45: 475 | C45: 595
...

Sheet Notes 2024-25
A1: Wipro Enterprises (P) Limited (Standalone)
A2: Notes to the Standalone Financial Statements (Selected Notes)
A3: Notes to the Standalone Financial Statements, year ended March 31, 2025 (Source: Annual Report 2024-25, pp.98-137)
A4: (Amount Rs. in millions, unless otherwise stated)
A6: Note 4. Property, plant and equipment - Net carrying value
B7: 2025 | C7: 2024
A8: Land | B8: 527 | C8: 527
A9: Buildings | B9: 3788 | C9: 3816
A10: Plant and Machinery | B10: 4952 | C10: 5085
A11: Furniture and Fixtures | B11: 155 | C11: 152
A12: Office Equipment | B12: 175 | C12: 132
A13: Vehicles | B13: 8 | C13: 12
A14: Total | B14: 9605 | C14: 9724
A16: Note 5. Capital work-in-progress & Intangible asset under development - ageing
B17: 2025 | C17: 2024
A18: CWIP - Less than 1 year | B18: 73 | C18: 102
A19: CWIP - 1-2 years | B19: 77 | C19: 25
A20: CWIP - 2-3 years | B20: 0 | C20: 1
A21: CWIP - More than 3 years | B21: 6 | C21: 13
A22: Total CWIP | B22: 156 | C22: 141
A23: Intangible asset under development - Less than 1 year | B23: 11 | C23: 86
A24: Intangible asset under development - 1-2 years | B24: 5 | C24: 37
A25: Intangible asset under development - 2-3 years | B25: 12 | C25: 11
A26: Intangible asset under development - More than 3 years | B26: 5 | C26: 6
A27: Total Intangible asset under development | B27: 33 | C27: 140
A29: Note 6. Right-of-use assets - movement
B30: 2025 | C30: 2024
A31: Balance at beginning of year | B31: 810 | C31: 800
A32: Additions | B32: 165 | C32: 111
A33: Deletions | B33: -44 | C33: 0
A34: Depreciation | B34: -85 | C34: -101
A35: Balance at end of year | B35: 846 | C35: 810
A37: Note 7. Goodwill and intangible assets - movement in Goodwill
B38: 2025 | C38: 2024
A39: Amount at the beginning of the year | B39: 1268 | C39: 362
A40: Addition during the year | B40: 0 | C40: 906
A41: Amount at the end of the year | B41: 1268 | C41: 1268
A42: Goodwill by segment: Consumer care and lighting 906/906; Infrastructure engineering 362/362.
A43: Net block of other intangible assets: 4,426 (2025), 3,983 (2024) [Technical know-how 92/100; Brands, patents, trademarks, distribution network & others 4,334/3,883]
A45: Note 8. Investments
...

Sheet BS 2024-25
A1: Wipro Enterprises (P) Limited (Standalone)
A2: Balance Sheet
A3: Balance Sheet as at March 31, 2025 (Source: Annual Report 2024-25, Wipro-Annual-Report-2024-25.pdf, p.80)
A4: (Amount Rs. in millions, unless otherwise stated)
A6: Particulars | B6: 2025 | C6: 2024
A7: ASSETS
A8: Non-current assets
A9: Property, plant and equipment | B9: 9605 | C9: 9724 | E9: =B9 -> 9605
A10: Capital work-in-progress | B10: 156 | C10: 141 | E10: =SUM(B10:B11) -> 189
A11: Intangible asset under development | B11: 33 | C11: 140 | E11: =B15 -> 58943
A12: Right of use assets | B12: 846 | C12: 810 | E12: =SUM(B12:B14,B16:B21) -> 25292
A13: Goodwill | B13: 1268 | C13: 1268
A14: Other intangible assets | B14: 4426 | C14: 3983
A15: Financial assets - Investments | B15: 58943 | C15: 33176
A16: Financial assets - Trade receivables | B16: 0 | C16: 45
A17: Financial assets - Derivative instruments | B17: 7 | C17: 0
A18: Financial assets - Loans | B18: 16522 | C18: 18265
A19: Financial assets - Other financial assets | B19: 144 | C19: 106
A20: Non current tax assets (net) | B20: 762 | C20: 788
A21: Other assets | B21: 1317 | C21: 1140
A22: Total non-current assets | B22: 94029 | C22: 69586
A23: Current assets
A24: Inventories | B24: 7119 | C24: 6402
A25: Financial assets - Investments | B25: 70625 | C25: 73332
A26: Financial assets - Trade receivables | B26: 5932 | C26: 7345
A27: Financial assets - Derivative instruments | B27: 10 | C27: 5
A28: Financial assets - Cash and cash equivalents | B28: 3278 | C28: 3309
A29: Financial assets - Loans | B29: 5749 | C29: 2727
A30: Financial assets - Other financial assets | B30: 1213 | C30: 1319
A31: Other assets | B31: 1678 | C31: 2063
A32: Assets held for sale | B32: 8 | C32: 53
A33: Total current assets | B33: 95612 | C33: 96555
A34: TOTAL ASSETS | B34: 189641 | C34: 166141
A35: EQUITY AND LIABILITIES
A36: Equity
A37: Share capital | B37: 4837 | C37: 4837
A38: Other equity | B38: 128849 | C38: 119159
A39: Total equity | B39: 133686 | C39: 123996
A40: Non-current liabilities
A41: Financial liabilities - Borrowings | B41: 21551 | C41: 11967
...

Sheet combined BS
B2: Particulars | C2: =2020+4 -> 2024 | D2: =2020+5 -> 2025 | E2: Particulars | F2: 2023 | G2: 2022
B3: ASSETS | E3: ASSETS
B4: Non-current assets | E4: Non-current assets
B5: Property, plant and equipment | C5: =IFERROR(INDEX('BS 2024-25'!C9:C58,MATCH(B5,'BS 2024-25'!A9:A58,0)),0) -> 9724 | E5: Property, plant and equipment
B6: Capital work-in-progress | C6: =IFERROR(INDEX('BS 2024-25'!C10:C59,MATCH(B6,'BS 2024-25'!A10:A59,0)),0) -> 141 | E6: Capital work-in-progress
B7: Intangible asset under development | C7: =IFERROR(INDEX('BS 2024-25'!C11:C60,MATCH(B7,'BS 2024-25'!A11:A60,0)),0) -> 140 | E7: Right of use assets
B8: Right of use assets | C8: =IFERROR(INDEX('BS 2024-25'!C12:C61,MATCH(B8,'BS 2024-25'!A12:A61,0)),0) -> 810 | E8: Goodwill
B9: Goodwill | C9: =IFERROR(INDEX('BS 2024-25'!C13:C62,MATCH(B9,'BS 2024-25'!A13:A62,0)),0) -> 1268 | E9: Other intangible assets
B10: Other intangible assets | C10: =IFERROR(INDEX('BS 2024-25'!C14:C63,MATCH(B10,'BS 2024-25'!A14:A63,0)),0) -> 3983 | E10: Financial assets - Investments
B11: Financial assets - Investments | C11: =IFERROR(INDEX('BS 2024-25'!C15:C64,MATCH(B11,'BS 2024-25'!A15:A64,0)),0) -> 33176 | E11: Financial assets - Trade receivables
B12: Financial assets - Trade receivables | C12: =IFERROR(INDEX('BS 2024-25'!C16:C65,MATCH(B12,'BS 2024-25'!A16:A65,0)),0) -> 45 | E12: Financial assets - Derivative instruments
B13: Financial assets - Derivative instruments | C13: =IFERROR(INDEX('BS 2024-25'!C17:C66,MATCH(B13,'BS 2024-25'!A17:A66,0)),0) -> 0 | E13: Financial assets - Loans
B14: Financial assets - Loans | C14: =IFERROR(INDEX('BS 2024-25'!C18:C67,MATCH(B14,'BS 2024-25'!A18:A67,0)),0) -> 18265 | E14: Financial assets - Other financial assets
B15: Financial assets - Other financial assets | C15: =IFERROR(INDEX('BS 2024-25'!C19:C68,MATCH(B15,'BS 2024-25'!A19:A68,0)),0) -> 106 | E15: Non current tax assets (net)
B16: Non current tax assets (net) | C16: =IFERROR(INDEX('BS 2024-25'!C20:C69,MATCH(B16,'BS 2024-25'!A20:A69,0)),0) -> 788 | E16: Other assets
... B30: TOTAL ASSETS | C30: =IFERROR(INDEX('BS 2024-25'!C34:C83,MATCH(B30,'BS 2024-25'!A34:A83,0)),0) -> 166141 | E30: EQUITY AND LIABILITIES
B31: EQUITY AND LIABILITIES | E31: Equity
B32: Equity | E32: Share capital
B33: Share capital | C33: =IFERROR(INDEX('BS 2024-25'!C37:C86,MATCH(B33,'BS 2024-25'!A37:A86,0)),0) -> 4837 | E33: Other equity
B34: Other equity | C34: =IFERROR(INDEX('BS 2024-25'!C38:C87,MATCH(B34,'BS 2024-25'!A38:A87,0)),0) -> 119159 | E34: Total equity
B35: Total equity | C35: =IFERROR(INDEX('BS 2024-25'!C39:C88,MATCH(B35,'BS 2024-25'!A39:A88,0)),0) -> 123996 | E35: Non-current liabilities
B36: Non-current liabilities | E36: Financial liabilities - Borrowings
B37: Financial liabilities - Borrowings | C37: =IFERROR(INDEX('BS 2024-25'!C41:C90,MATCH(B37,'BS 2024-25'!A41:A90,0)),0) -> 11967 | E37: Financial liabilities - Lease liabilities
B38: Financial liabilities - Lease liabilities | C38: =IFERROR(INDEX('BS 2024-25'!C42:C91,MATCH(B38,'BS 2024-25'!A42:A91,0)),0) -> 79 | E38: Financial liabilities - Derivative instruments
B39: Financial liabilities - Derivative instruments | C39: =IFERROR(INDEX('BS 2024-25'!C43:C92,MATCH(B39,'BS 2024-25'!A43:A92,0)),0) -> 1255 | E39: Provisions
B40: Provisions | C40: =IFERROR(INDEX('BS 2024-25'!C44:C93,MATCH(B40,'BS 2024-25'!A44:A93,0)),0) -> 320 | E40: Deferred tax liabilities (net)
B41: Deferred tax liabilities (net) | C41: =IFERROR(INDEX('BS 2024-25'!C45:C94,MATCH(B41,'BS 2024-25'!A45:A94,0)),0) -> 1620 | E41: Total non-current liabilities
B42: Total non-current liabilities | C42: =IFERROR(INDEX('BS 2024-25'!C46:C95,MATCH(B42,'BS 2024-25'!A46:A95,0)),0) -> 15241 | E42: Current liabilities
B43: Current liabilities | E43: Financial liabilities - Borrowings
B44: Financial liabilities - Borrowings | C44: =IFERROR(INDEX('BS 2024-25'!C48:C97,MATCH(B44,'BS 2024-25'!A48:A97,0)),0) -> 11032 | E44: Financial liabilities - Lease liabilities
B45: Financial liabilities - Lease liabilities | C45: =IFERROR(INDEX('BS 2024-25'!C49:C98,MATCH(B45,'BS 2024-25'!A49:A98,0)),0) -> 27 | E45: Financial liabilities - Derivative liabilities
B46: Financial liabilities - Derivative liabilities | C46: =IFERROR(INDEX('BS 2024-25'!C50:C99,MATCH(B46,'BS 2024-25'!A50:A99,0)),0) -> 452 | E46: Trade payables - dues of micro & small enterprises
B47: Trade payables - dues of micro & small enterprises | C47: =IFERROR(INDEX('BS 2024-25'!C51:C100,MATCH(B47,'BS 2024-25'!A51:A100,0)),0) -> 1003 | E47: Trade payables - dues of other creditors
B48: Trade payables - dues of other creditors | C48: =IFERROR(INDEX('BS 2024-25'!C52:C101,MATCH(B48,'BS 2024-25'!A52:A101,0)),0) -> 10100 | E48: Financial liabilities - Other financial liabilities
B49: Financial liabilities - Other financial liabilities | C49: =IFERROR(INDEX('BS 2024-25'!C53:C102,MATCH(B49,'BS 2024-25'!A53:A102,0)),0) -> 2164 | E49: Other liabilities
B50: Other liabilities | C50: =IFERROR(INDEX('BS 2024-25'!C54:C103,MATCH(B50,'BS 2024-25'!A54:A103,0)),0) -> 855 | E50: Provisions
B51: Provisions | C51: =IFERROR(INDEX('BS 2024-25'!C55:C104,MATCH(B51,'BS 2024-25'!A55:A104,0)),0) -> 163 | E51: Current tax liabilities (net)
B52: Current tax liabilities (net) | C52: =IFERROR(INDEX('BS 2024-25'!C56:C105,MATCH(B52,'BS 2024-25'!A56:A105,0)),0) -> 1108 | E52: Total current liabilities
B53: Total current liabilities | C53: =IFERROR(INDEX('BS 2024-25'!C57:C106,MATCH(B53,'BS 2024-25'!A57:A106,0)),0) -> 26904 | E53: TOTAL EQUITY AND LIABILITIES
B54: TOTAL EQUITY AND LIABILITIES | C54: =IFERROR(INDEX('BS 2024-25'!C58:C107,MATCH(B54,'BS 2024-25'!A58:A107,0)),0) -> 166141

Sheet CF 2024-25
A1: Wipro Enterprises (P) Limited (Standalone)
A2: Statement of Cash Flows
A3: Statement of Cash Flows for the year ended March 31, 2025 (Source: Annual Report 2024-25, pp.83-84)
A4: (Amount Rs. in millions, unless otherwise stated)
A6: Particulars | B6: 2025 | C6: 2024
A7: A. Cash flows from operating activities
A8: Profit before tax | B8: 13006 | C8: 16007
A9: Depreciation and amortization | B9: 1311 | C9: 1830
A10: Interest on borrowings | B10: 2223 | C10: 1478
A11: FV change of Investment | B11: 710 | C11: -174
A12: Dividend / interest income | B12: -4285 | C12: -4008
A13: Net (gain)/loss on sale of current investments | B13: -3462 | C13: -2729
A14: Net (gain)/loss on sale of associates | B14: -1452 | C14: -1392
A15: Net (gain)/loss on sale of PP&E and intangible assets | B15: -98 | C15: -1
A16: Change in fair value of consideration | B16: 14 | C16: -614
A17: Allowance for doubtful receivables | B17: -258 | C17: 41
A18: Net foreign exchange differences on non-operating items | B18: 952 | C18: -93
A19: Working capital changes - Trade receivables | B19: 764 | C19: -439
... A25: Net cash generated from operating activities | B25: 4558 | C25: 8621
A26: B. Cash flows from investing activities
A27: Acquisition of PP&E including capital advances | B27: -1410 | C27: -861
A28: Proceeds from sale of PP&E | B28: 125 | C28: 28
A29: Investment in associates | B29: -20 | C29: -150
A30: Purchase of investments | B30: -159319 | C30: -75423
A31: Proceeds from sale/maturity of current investments | B31: 144341 | C31: 72957
A32: Proceeds from sale of investment in associates | B32: 1457 | C32: 1495
A33: Payment for business acquisitions, net of cash acquired | B33: 0 | C33: -3388
A34: Investment in subsidiaries | B34: -2725 | C34: 0
A35: Loan to subsidiaries | B35: -3072 | C35: -3820
A36: Loan from subsidiaries | B36: 1793 | C36: 3200
A37: Amount received on liquidation of subsidiary | B37: 0 | C37: 48
A38: Interest income received | B38: 1587 | C38: 3235
... A40: Net cash used in investing activities | B40: -17204 | C40: -2609
A41: C. Cash flows from financing activities
A42: Interest paid on borrowings | B42: -2256 | C42: -1608
A43: Payment for contingent consideration | B43: 0 | C43: -733
A44: Proceeds from borrowings | B44: 21342 | C44: 7481
A45: Payment towards share capital reduction | B45: -7 | C45: 0
A46: Repayment of lease liabilities | B46: -93 | C46: -123
A47: Repayment of borrowings | B47: -6371 | C47: -9317
...

Sheet PL 2024-25
A1: Wipro Enterprises (P) Limited (Standalone)
A2: Statement of Profit and Loss
A3: Statement of Profit and Loss for the year ended March 31, 2025 (Source: Annual Report 2024-25, p.81). Revenue from operations and Other expenses for 2024 shown as restated per Note 49 in this report; figures may therefore differ slightly from the FY2023-24 report's originally reported figures.
A4: (Amount Rs. in millions, unless otherwise stated)
A6: Particulars | B6: 2025 | C6: 2024
A7: REVENUE
A8: Revenue from operations (Restated for 2024, refer Note 49) | B8: 72308 | C8: 71475
A9: Other income | B9: 9191 | C9: 9583
A10: Total income | B10: 81499 | C10: 81058
A11: EXPENSES
A12: Cost of materials consumed | B12: 39567 | C12: 38297
A13: Purchases of stock-in-trade | B13: 1434 | C13: 530
A14: Changes in inventories of finished products, WIP and stock-in-trade | B14: -293 | C14: 697
A15: Employee benefits expense | B15: 6467 | C15: 6264
A16: Finance costs | B16: 2223 | C16: 1478
A17: Depreciation, amortisation and impairment expense | B17: 1311 | C17: 1830
A18: Other expenses (Restated for 2024, refer Note 49) | B18: 17784 | C18: 15955
A19: Total Expenses | B19: 68493 | C19: 65051
A20: Profit before tax | B20: 13006 | C20: 16007
A21: Tax expense
A22: Current tax | B22: 3157 | C22: 2766
A23: Deferred tax | B23: 73 | C23: 609
A24: Total tax expenses | B24: 3230 | C24: 3375
A25: Profit for the year | B25: 9776 | C25: 12632
A26: Other comprehensive income, net of taxes
A27: Remeasurement of defined benefit liability/asset (net of tax) | B27: -19 | C27: -85
A28: Net change in FV of financial instruments through OCI (net of tax) | B28: 65 | C28: 122
A29: Net change in FV of cash flow hedge (net of tax) | B29: -125 | C29: -67
A30: Total other comprehensive income for the year, net of taxes | B30: -79 | C30: -30
A31: Total comprehensive income for the year | B31: 9697 | C31: 12602
A32: Earnings per equity share (par value Rs.10 each)
A33: Weighted average equity shares for computing basic and diluted EPS | B33: 483659648 | C33: 483662163
A34: Basic and diluted EPS (Rs.) | B34: 20.21 | C34: 26.12

Sheet HistoriacalIFLS
B2: ="Historical Financial Statement - "&'[1]Data Sheet'!C1 -> Historical Financial Statement - Wipro Ltd
B3: Years | C3: ='[1]Data Sheet'!E16 -> 43921 | D3: ='[1]Data Sheet'!F16 -> 44286 | E3: ='[1]Data Sheet'!G16 -> 44651 | F3: ='[1]Data Sheet'!H16 -> 45016 | G3: ='[1]Data Sheet'!I16 -> 45382 | H3: ='[1]Data Sheet'!J16 -> 45747
B5: Income Statment
B7: Sales | C7: =IFERROR('PL 2020-21'!C8,0) -> 47775 | D7: =IFERROR('PL 2020-21'!B8,0) -> 51658 | E7: =IFERROR('PL 2022-23'!C8,0) -> 57884 | F7: =IFERROR('PL 2022-23'!B8,0) -> 70052 | G7: =IFERROR('PL 2024-25'!C8,0) -> 71475 | H7: =IFERROR('PL 2024-25'!B8,0) -> 72308
B8: sales Increase | D8: =D7/C7-1 -> 0.081276818 | E8: =E7/D7-1 -> 0.12052344 | F8: =F7/E7-1 -> 0.21021353 | G8: =G7/F7-1 -> 0.020313481 | H8: =H7/G7-1 -> 0.011654425
B9: Other Income | C9: =IFERROR('PL 2020-21'!C9,0) -> 4900 | D9: =IFERROR('PL 2020-21'!B9,0) -> 6905 | E9: =IFERROR('PL 2022-23'!C9,0) -> 5711 | F9: =IFERROR('PL 2022-23'!B9,0) -> 7572 | G9: =IFERROR('PL 2024-25'!C9,0) -> 9583 | H9: =IFERROR('PL 2024-25'!B9,0) -> 9191
D10: =D9/C9-1 -> 0.40918367 | E10: =E9/D9-1 -> -0.17291818 | F10: =F9/E9-1 -> 0.32586237 | G10: =G9/F9-1 -> 0.26558373 | H10: =H9/G9-1 -> -0.040905771
B11: Total Revenue | C11: =IFERROR(SUM(C7,C9),0) -> 52675 | D11: =IFERROR(SUM(D7,D9),0) -> 58563 | E11: =IFERROR(SUM(E7,E9),0) -> 63595 | F11: =IFERROR(SUM(F7,F9),0) -> 77624 | G11: =IFERROR(SUM(G7,G9),0) -> 81058 | H11: =IFERROR(SUM(H7,H9),0) -> 81499
D12: =D11/C11-1 -> 0.11177978 | E12: =E11/D11-1 -> 0.08592456 | F12: =F11/E11-1 -> 0.2205991 | G12: =G11/F11-1 -> 0.044238895 | H12: =H11/G11-1 -> 0.0054405487
B13: COGS | C13: =IFERROR(SUM('PL 2020-21'!C12:C14),0) -> 25307 | D13: =IFERROR(SUM('PL 2020-21'!B12:B14),0) -> 30003 | E13: =IFERROR(SUM('PL 2021-22'!B12:B14),0) -> 34114 | F13: =IFERROR(SUM('PL 2022-23'!B12:B14),0) -> 41330 | G13: =IFERROR(SUM('PL 2024-25'!C12:C14),0) -> 39524 | H13: =IFERROR(SUM('PL 2024-25'!B12:B14),0) -> 40708
B14: COGS%Sales | C14: =C13/C7 -> 0.52971219 | D14: =D13/D7 -> 0.58080065 | E14: =E13/E7 -> 0.58935112 | F14: =F13/F7 -> 0.58999029 | G14: =G13/G7 -> 0.55297657 | H14: =H13/H7 -> 0.56298058
B16: Gross Profit | C16: =C11-C13 -> 27368 | D16: =D11-D13 -> 28560 | E16: =E11-E13 -> 29481 | F16: =F11-F13 -> 36294 | G16: =G11-G13 -> 41534 | H16: =H11-H13 -> 40791
B17: GrossMargins | C17: =C16/C7 -> 0.57285191 | D17: =D16/D7 -> 0.55286693 | E17: =E16/E7 -> 0.50931173 | F17: =F16/F7 -> 0.51810084 | G17: =G16/G7 -> 0.58109829 | H17: =H16/H7 -> 0.56412845
B19: Employee Benefits Expenses | C19: =IFERROR('PL 2020-21'!C15,0) -> 4077 | D19: =IFERROR('PL 2020-21'!B15,0) -> 4518 | E19: =IFERROR('PL 2022-23'!C15,0) -> 4944 | F19: =IFERROR('PL 2022-23'!B15,0) -> 5585 | G19: =IFERROR('PL 2024-25'!C15,0) -> 6264 | H19: =IFERROR('PL 2024-25'!B15,0) -> 6467
B20: Emp Exp%Sales | C20: =C19/C7 -> 0.08533752 | D20: =D19/D7 -> 0.087459832 | E20: =E19/E7 -> 0.085412204 | F20: =F19/F7 -> 0.079726489 | G20: =G19/G7 -> 0.087639035 | H20: =H19/H7 -> 0.089436853
B22: Other exp | C22: =IFERROR('PL 2020-21'!C18,0) -> 11893 | D22: =IFERROR('PL 2020-21'!B18,0) -> 11101 | E22: =IFERROR('PL 2022-23'!C18,0) -> 11844 | F22: =IFERROR('PL 2022-23'!B18,0) -> 15329 | G22: =IFERROR('PL 2024-25'!C18,0) -> 15955 | H22: =IFERROR('PL 2024-25'!B18,0) -> 17784
C23: =C22/C7 -> 0.24893773 | D23: =D22/D7 -> 0.21489411 | E23: =E22/E7 -> 0.20461613 | F23: =F22/F7 -> 0.21882316 | G23: =G22/G7 -> 0.2232249 | H23: =H22/H7 -> 0.24594789
B24: EBITDA | C24: =C16-SUM(C19,C22) -> 11398 | D24: =D16-SUM(D19,D22) -> 12941 | E24: =E16-SUM(E19,E22) -> 12693 | F24: =F16-SUM(F19,F22) -> 15380 | G24: =G16-SUM(G19,G22) -> 19315 | H24: =H16-SUM(H19,H22) -> 16540
B25: EBITDA Margins | C25: =C24/C7 -> 0.23857666 | D25: =D24/D7 -> 0.25051299 | E25: =E24/E7 -> 0.21928339 | F25: =F24/F7 -> 0.21955119 | G25: =G24/G7 -> 0.27023435 | H25: =H24/H7 -> 0.22874371
